Workbook

Sheet Start Here
A1: RESEARCH HOME · R17 | B1: Purpose / rule | C1: Open / exact range | D1: Status | E1: Scope | F1: Owner / updater | G1: Updated UTC | H1: Notes
A2: Entry | B2: Use this compact view; full policy only when needed | C2: https://drive.google.com/file/d/1hBph5Fpxd5dVrolNkvzU8nb7xpxUiUdc/view | D2: ACTIVE | E2: Operations | F2: Any worker | G2: 2026-09-17T16:25:48.473074Z | H2: R17 supersedes R16 entry overhead; exact scientific gates retained
A3: Review work | B3: Pick oldest eligible nonauthor review; reconcile prior verdicts first | C3: https://docs.google.com/spreadsheets/d/1O6x8ivmaVUxYqKmCOXmToIHpMXqDI362ibqBl8HY8no/edit#gid=2026091702 | D3: LIVE QUEUE | E3: MATH / COMPUTE / OPS | F3: Claimed reviewer | G3: 2026-09-17T16:25:48.473074Z | H3: Same-provider technical review allowed; org independence remains separate
A4: Find a file | B4: Search title or ID, then read exact source | C4: https://docs.google.com/spreadsheets/d/1O6x8ivmaVUxYqKmCOXmToIHpMXqDI362ibqBl8HY8no/edit#gid=2026091703 | D4: METADATA SNAPSHOT | E4: Active-tree baseline + bounded updates | F4: Maintenance | G4: 2026-09-17T16:25:48.473074Z | H4: Catalog presence or omission does not prove mathematical truth or global completeness
A5: Quarantine | B5: Check exclusions and restoration tests before consumption | C5: https://docs.google.com/spreadsheets/d/1O6x8ivmaVUxYqKmCOXmToIHpMXqDI362ibqBl8HY8no/edit#gid=2026091704 | D5: ACTIVE | E5: Duplicates / defective scopes / unverified | F5: Any worker | G5: 2026-09-17T16:25:48.473074Z | H5: Frozen members are excluded by carrier+path+hash; keep bytes intact
A6: Claims and handoff | B6: Append unique event; read contenders; verify source/head before commit | C6: https://docs.google.com/spreadsheets/d/1O6x8ivmaVUxYqKmCOXmToIHpMXqDI362ibqBl8HY8no/edit#gid=2026091705 | D6: COOPERATIVE | E6: One exact target per claim | F6: Each session | G6: 2026-09-17T16:25:48.473074Z | H6: Not compare-and-swap; conflicting publication heads require reconciliation
A7: Claim expiry | B7: 120 minutes after valid heartbeat | C7: Work Events; legacy Active Work Claims | D7: ACTIVE | E7: Exact object + role | F7: Each session | G7: 2026-09-17T16:25:48.473074Z | H7: No resurrection by late heartbeat; use a new claim
A8: Cold entry | B8: This view plus needed queue/events in one multi-range read | C8: Read the allocated compact Start Here view after checking grid metadata (currently A1:H100, 100 rows). Resolve required stable keys; treat truncation as incomplete. Review Queue and Work Events use current target keys and relevant latest events, not assumed fixed prefixes. | D8: BOUND READ | E8: Control/navigation only | F8: Incoming worker | G8: 2026-09-17T16:25:48.473074Z | H8: Expand these bounded ranges when the queue/events grow; source reads, publication and verification are additional calls
A9: Cached continuation | B9: Check live policy, claim, source identity and output head | C9: https://drive.google.com/file/d/1fRS3BP82tCJC_K-hFCSm26Lbfv3EFoxq/view | D9: SCOPED REVALIDATION | E9: Changed dependencies only | F9: Incoming worker | G9: 2026-09-17T16:25:48.473074Z | H9: Bad/missing/stale handoff expands scoped reads; no automatic whole-Drive crawl
A10: Review ladder | B10: 7 days prioritize; 14 decompose; 30 escalate | C10: Review Queue age/action columns | D10: ACTIVE | E10: Age is prioritization, never approval | F10: Daily pickup + session entry | G10: 2026-09-17T16:25:48.473074Z | H10: Old date basis is explicit; metadata refresh does not reset substantive age
A11: Review credit | B11: Nonauthor same-provider technical pass is permitted | C11: PASS_TECHNICAL and independence are separate | D11: ACTIVE | E11: Author/coauthor checks are internal | F11: Reviewer | G11: 2026-09-17T16:25:48.473074Z | H11: Different provider can still be dependent; disclose exposure and coauthorship
A12: Publish states | B12: DRAFT → CANDIDATE_VERIFIED → READY_FOR_REVIEW → REVIEWED/AMEND | C12: One delivery manifest; immutable candidates | D12: ACTIVE | E12: Task completion is scoped | F12: Publisher | G12: 2026-09-17T16:25:48.473074Z | H12: Do not mark theorem complete merely because registration succeeded
... A23: Operator precedence | B23: Current direct user instruction controls operations | C23: Research Home / R17 policy | D23: ACTIVE | E23: No legacy budget or provider deadlock | F23: Owner | G23: 2026-09-17T16:25:48.473074Z | H23: No fabricated review or mathematical closure
A24: Audit coverage | B24: =COUNTA('File Catalog'!A2:A3500)&" catalog entries; "&COUNTA('Review Queue'!A2:A500)&" review routes; "&COUNTA('Quarantine Index'!A2:A300)&" exclusions/containers" -> 2952 catalog entries; 40 review routes; 22 exclusions/containers | C24: https://drive.google.com/file/d/1g5UP_KYlvPmx7LFwjGk6qK5QZLnL1hLj/view | D24: BOUNDED AUDIT | E24: No global proof closure; current release and verified deltas | F24: ROUND5 | G24: 2026-09-17T17:19:16.450Z | H24: RN5 adds five scoped exclusions and LM004 author-line erratum; frozen science retained
A25: Format accessibility | B25: Source map and 392 published reading copies | C25: https://docs.google.com/spreadsheets/d/1hO3MPQwtAiEjCGdOjZJTbB8fKIvt_3GU6KgxPGTPiLg/edit?usp=drivesdk | D25: PUBLISHED / VERIFIED | E25: Read Exceptions and copy verification scope | F25: ACCESS-20260917-4121 | G25: 2026-09-17T23:57:33.664Z | H25: 4,456 inventory items; 77 archives; 6,034 reading links. Report: https://drive.google.com/file/d/1sORvjt806v3z1rPAlH8I7CflxEZDUx8X/view?usp=drivesdk
A26: Folder structure | B26: Folder Directory, Folder Rules and Path Changes | C26: https://docs.google.com/spreadsheets/d/1hO3MPQwtAiEjCGdOjZJTbB8fKIvt_3GU6KgxPGTPiLg/edit?usp=drivesdk | D26: VERIFIED TARGETED UPDATE | E26: 755 folder rows; 238 mapped path changes | F26: STRUCTURE-20260918-C2087 | G26: 2026-09-18T00:17:48.912Z | H26: 184 folders checked through targeted live metadata; other rows retain the dated baseline. Folder Directory shows the basis.
A27: Naming and templates | B27: OP-ORG-20260918-v1.0; REVIEW_SCAFFOLD_V1 | C27: https://drive.google.com/file/d/1O_P3jbsHmKmA2U8OCks2_Hxf7W86Ae_Q/view?usp=drivesdk | D27: INSTALLED | E27: Operational naming and navigation only | F27: STRUCTURE-20260918-C2087 | G27: 2026-09-18T00:17:48.912Z | H27: Current triage index: https://drive.google.com/file/d/14eIT8SEj20pwUqnJ8DSjrrQcY9g4Ytjt/view?usp=drivesdk; existing T4/T5 charters and all 15 review scaffolds verified.
A28: Structure completion | B28: 18 September folder optimization report and rollback record | C28: https://drive.google.com/file/d/14z_m-gec3YRFWmJJksoJNRdT9_EN8h1C/view?usp=drivesdk | D28: COMPLETE | E28: 20 structure edits verified; source map updated | F28: STRUCTURE-20260918-C2087 | G28: 2026-09-18T00:23:00.610Z | H28: Report includes scope and readback evidence; guarded rollback: https://drive.google.com/file/d/1f14Tr1Pi1nrcByCFrx-8EnkuX_9n7SLG/view?usp=drivesdk
A29: Reusable operations | B29: Search by intended action; match scope and refresh exact source | C29: https://docs.google.com/spreadsheets/d/1O6x8ivmaVUxYqKmCOXmToIHpMXqDI362ibqBl8HY8no/edit#gid=2026091801 | D29: 15 SCOPED ENTRIES | E29: 8 conditional rules; 3 candidates; 2 negative rules; 2 boundaries | F29: OP-REUSE-20260918-66ba2ff9 | G29: 2026-09-18T03:02:43.860Z | H29: Guide: https://docs.google.com/document/d/1e7MLN7QbnHltfOq57jE7F738lEq5zM9PF1QhhkM9bdM/edit — usefulness UNMEASURED; source states preserved
A30: Operation trials | B30: Log prospective fixed-library / lemma-cache / operation comparisons | C30: https://docs.google.com/spreadsheets/d/1O6x8ivmaVUxYqKmCOXmToIHpMXqDI362ibqBl8HY8no/edit#gid=2026091802 | D30: READY; NO TRIALS YET | E30: Matched budgets, verified outcomes, overhead and held-out tasks | F30: OP-REUSE-20260918-66ba2ff9 | G30: 2026-09-18T03:02:43.860Z | H30: Exposed retrieval controls are not held-out usefulness evidence. Keep failures; no self-citation credit.
A31: Support withdrawal and scheduling | B31: Preserve premises, distinguish scheduling from truth, and require exact survivor warrants | C31: https://drive.google.com/file/d/1YvukN4MGwEoLcsLJRQjPjoESAjWsNbr_/view | https://github.com/d6g8k5htny-coder/main/pull/4 | D31: OPS SAFEGUARDS ACTIVE / CODE PILOT UNREVIEWED / SCIENCE NOT MIGRATED | E31: New work only; loss-only candidate checks; no scientific verdict, restoration, broad migration or automatic deployment | F31: R17 Work Events; RV-WITHDRAWAL-20260921-01 nonauthor technical review | G31: 2026-09-21T17:05:02Z | H31: OP-WITHDRAWAL-20260921-v1.0; source SHA256 0e9fcb229e2cdfab18c7aba6dfc6ec8c102611d4f463439cdb3290fc8d6e98e9. Recheck current source and exact heads at each task boundary. Do not invent dependency coverage or treat closed work as discharge.
A32: Governance rollout audit | B32: Re-evaluate installed rules for intent, typed scope, consumer migration and stage-skipping | C32: https://drive.google.com/file/d/1cKPOpv1foB7F7aBA-N0O8vtzetPWKjyR/view | https://github.com/d6g8k5htny-coder/main/pull/4 | D32: SCOPED CORRECTION v1.1 / CODE SHADOW / AUDIT INCOMPLETE | E32: Operational governance; no scientific status changes | F32: Any worker may report conflicts; changes require scoped evidence | G32: 2026-09-21T22:18:54Z | H32: R17's authorized supersessions remain effective; no retired-rule revival. Phase material behavior changes; guarded semantics-preserving maintenance has a bounded path. Binding classes require protocol/version. Source policy SHA256 2cb52776552681f9f17ba5cb5d50fc81b05003dd75e6f31893a7d427a51713d5. Review RV-ROLLOUT-R2-20260921-01 remains OPEN; no scientific migration or global uptake claim.
A33: Standing owner authorization — all models | B33: All project work preapproved; proceed without renewed permission or owner approval. | C33: https://drive.google.com/file/d/1N-afVwLVTloSB79GtEK1Fhfx7vdI4_b7/view | D33: EFFECTIVE / NO OWNER-APPROVAL WAIT | E33: All models; GitHub and Drive research, integration and administration; until Dylan changes it. | F33: Dylan Roy — corrected direct instruction; transcribed by ChatGPT | G33: 2026-09-23T19:35:04Z | H33: OP-AUTONOMY-20260923-v1.0 supersedes older project-specific owner-permission restrictions and the 48-hour limit. SHA256 1d51a9c68940b6047618286d7f9b3c55146d2650fe9d23d363e7d6133f7f4362. Preapproval is permission, not proof or a test result. No need to wait for all mirrors to update.

Sheet Review Queue
A1: Review key | B1: Domain | C1: Exact object | D1: Technical status | E1: Next action | F1: Packet or source | G1: Prior review / exposure | H1: Independence status | I1: Request time UTC | J1: Date basis | K1: Last substantive review UTC | L1: Age days | M1: Aging action | N1: Author / provider | O1: Body SHA-256 | P1: Body bytes | Q1: Reviewer / claim | R1: Verdict artifact | S1: Scope / dependencies
A2: RV-LM003-MAIN | B2: MATH | C2: LCR-DER-014-v1.0 | D2: NEEDS_RECONCILIATION | E2: Verify and register the existing exact technical verdict; perform new mathematics only for missing or changed criteria | F2: https://docs.google.com/document/d/13aLHEMKmN9n1v7PLSGbs_u_7dQ-Euvc91eWC4veIP0g/edit | G2: CURRENT EXACT BODY REPRODUCED / SAME-LINE MATHEMATICS PASS / ORGANIZATIONALLY DISTINCT EXACT-HASH THEOREM VERDICT OPEN / NONTERMINAL | H2: EXTERNAL_REVIEW_OPEN | I2: 2026-07-25T22:45:00Z | J2: Legacy review-routing record; request onset not independently reconstructed | L2: =IF(I2="","",MAX(0,TODAY()-DATE(VALUE(LEFT(I2,4)),VALUE(MID(I2,6,2)),VALUE(MID(I2,9,2))))) -> 60 | M2: =IF(L2="","UNKNOWN",IF(D2="PASS_TECHNICAL","EXTERNAL ONLY",IF(L2>=30,"ESCALATE",IF(L2>=14,"DECOMPOSE",IF(L2>=7,"PRIORITIZE","NEW"))))) -> ESCALATE | N2: OpenAI; exact author session to be disclosed | O2: 5173d26d6bfaae5ef65a8ae2d0ca9b829a291be3f7dacaba82bb38d2526bb83e | P2: 6874 | Q2: UNASSIGNED | S2: H1–H5 imply exact determinant-weighted boundary-layer probability O(r^3). | One organizationally distinct reviewer must bind an affirmative or corrective theorem verdict to the exact 6,874-byte body, checking support inclusion, empty intervals, the r^5 numerator, and normalizer direction.
A3: RV-LM004-MAIN | B3: MATH | C3: LCR-DER-016-v1.1 | D3: PASS_TECHNICAL | E3: Obtain one qualifying organizationally distinct LCR-REQ-039 exact-object verdict; do not repeat OpenAI technical work absent a new defect or hash change | F3: https://docs.google.com/document/d/1LKbFbisGVoEwzm3W-23-rdnzEF6crjxYCK-3G3J5OrA/edit | G3: CURRENT v1.1 EXACT BODY REPRODUCED / S2 SAME-FAMILY PASS RECONCILED / ANTHROPIC IMPORT RECONSTRUCTION SUPPORTS C1 TRANSFER BUT DID NOT ISSUE THE ISOLATED ACCEPTED EXACT-HASH VERDICT / NONTERMINAL | H3: EXTERNAL_REVIEW_OPEN | I3: 2026-07-25T21:12:00Z | J3: Legacy review-routing record; request onset not independently reconstructed | K3: 2026-09-17T16:55:40.169Z | L3: =IF(I3="","",MAX(0,TODAY()-DATE(VALUE(LEFT(I3,4)),VALUE(MID(I3,6,2)),VALUE(MID(I3,9,2))))) -> 60 | M3: =IF(L3="","UNKNOWN",IF(D3="PASS_TECHNICAL","EXTERNAL ONLY",IF(L3>=30,"ESCALATE",IF(L3>=14,"DECOMPOSE",IF(L3>=7,"PRIORITIZE","NEW"))))) -> EXTERNAL ONLY | N3: OpenAI; exact author session to be disclosed | O3: d43179f3abfd7e93f988725f3b89a5826cc71e0fa04840f65c7f93f3359d0f87 | P3: 10416 | Q3: Prior OpenAI technical reconciliation; ROUND5 author-line erratum; zero org credit | R3: https://drive.google.com/file/d/1QKujzzkp_nzCWFLky9ZayTzP_fbStxry/view | S3: Exact 10,416-byte body unchanged; duplicate-term finding withdrawn. Existing technical disposition retained. Qualifying organizationally distinct LCR-REQ-039 exact-hash verdict remains open.
A4: RV-LM006-MAIN | B4: MATH | C4: LCR-DER-019-v1.0 | D4: NEEDS_RECONCILIATION | E4: Verify and register the existing exact technical verdict; perform new mathematics only for missing or changed criteria | F4: https://docs.google.com/document/d/13aLHEMKmN9n1v7PLSGbs_u_7dQ-Euvc91eWC4veIP0g/edit | G4: EXTERNAL BYTE/HASH REPRODUCTION PASS / SAME-LINE THEOREM PASS / FULL ORGANIZATIONALLY DISTINCT THEOREM VERDICT OPEN / NONTERMINAL | H4: EXTERNAL_REVIEW_OPEN | I4: 2026-07-25T22:45:00Z | J4: Legacy review-routing record; request onset not independently reconstructed | L4: =IF(I4="","",MAX(0,TODAY()-DATE(VALUE(LEFT(I4,4)),VALUE(MID(I4,6,2)),VALUE(MID(I4,9,2))))) -> 60 | M4: =IF(L4="","UNKNOWN",IF(D4="PASS_TECHNICAL","EXTERNAL ONLY",IF(L4>=30,"ESCALATE",IF(L4>=14,"DECOMPOSE",IF(L4>=7,"PRIORITIZE","NEW"))))) -> ESCALATE | N4: OpenAI; exact author session to be disclosed | O4: 239ed094f70aa4352021572ad8bdc0c6ac6404edab4e1d7e61addec0c6659150 | P4: 9147 | Q4: UNASSIGNED | S4: Exact full-field typed normalizer satisfies Z_r/r²→E[Q_L²1{Q_L<0}]∈(0,∞). | Obtain a full organizationally distinct theorem verdict on the exact body: exact-torus Q_L limit, type boundary, uniform integrability, positivity, and two-sided r^2 bounds. Do not repeat transport-only work.
A5: RV-LM009-MAIN | B5: MATH | C5: LCR-DER-027-v1.0 | D5: PASS_TECHNICAL | E5: Finish external exact-object predicate; do not repeat Markov proof | F5: https://docs.google.com/document/d/17G4cRezBpLk9E1ds5rA615caPY9P19_JA80L57sF2ek/edit | G5: CURRENT v1.0 EXACT BODY REPRODUCED / SAME-LINE MATHEMATICS PASS / ORGANIZATIONALLY DISTINCT EXACT-HASH REVIEW OPEN / NONTERMINAL | H5: EXTERNAL_REVIEW_OPEN | I5: 2026-07-26T13:24:44Z | J5: Legacy review-routing record; request onset not independently reconstructed | K5: 2026-09-17T16:25:48.473074Z | L5: =IF(I5="","",MAX(0,TODAY()-DATE(VALUE(LEFT(I5,4)),VALUE(MID(I5,6,2)),VALUE(MID(I5,9,2))))) -> 59 | M5: =IF(L5="","UNKNOWN",IF(D5="PASS_TECHNICAL","EXTERNAL ONLY",IF(L5>=30,"ESCALATE",IF(L5>=14,"DECOMPOSE",IF(L5>=7,"PRIORITIZE","NEW"))))) -> EXTERNAL ONLY | N5: OpenAI; exact author session to be disclosed | O5: ccc07d959428519733c7fdf6c72f1bce63a40d0b0dc956ce0fe9f2ec459eb0b1 | P5: 3919 | Q5: OPS4 nonauthor / exposed / OpenAI | R5: https://drive.google.com/file/d/1cDFrsYx8l6jfGzQzYi0RemAw8Tv4d2qk/view | S5: All fixed moments imply REG_r failure is O(r^N) for every requested N. | One organizationally distinct reviewer must bind an affirmative or corrective verdict to the exact 3,919-byte body under LCR-REQ-029-v1.0 or the current LCR-REQ-052-v1.1 tail bundle, checking exponent selection, radius direction, exact U crosswalk, conditioned-to-Palm exponent doubling, and the no-fixed-exponential-tail firewall.
A6: RV-LM010-MAIN | B6: MATH | C6: LCR-DER-030-v1.1 | D6: NEEDS_RECONCILIATION | E6: Verify and register the existing exact technical verdict; perform new mathematics only for missing or changed criteria | F6: https://docs.google.com/document/d/13aLHEMKmN9n1v7PLSGbs_u_7dQ-Euvc91eWC4veIP0g/edit | G6: CURRENT REPAIRED v1.1 BODY REPRODUCED / SAME-LINE MATHEMATICS PASS / ORGANIZATIONALLY DISTINCT EXACT-HASH THEOREM VERDICT OPEN / NONTERMINAL | H6: EXTERNAL_REVIEW_OPEN | I6: 2026-07-25T22:45:00Z | J6: Legacy review-routing record; request onset not independently reconstructed | L6: =IF(I6="","",MAX(0,TODAY()-DATE(VALUE(LEFT(I6,4)),VALUE(MID(I6,6,2)),VALUE(MID(I6,9,2))))) -> 60 | M6: =IF(L6="","UNKNOWN",IF(D6="PASS_TECHNICAL","EXTERNAL ONLY",IF(L6>=30,"ESCALATE",IF(L6>=14,"DECOMPOSE",IF(L6>=7,"PRIORITIZE","NEW"))))) -> ESCALATE | N6: OpenAI; exact author session to be disclosed | O6: 05e0f20f0feb938ab7fca43c49b1f70fd0b8a492138ae805a418a5d028177ef2 | P6: 9335 | Q6: UNASSIGNED | S6: Exact good-boundary numerator uses subweight while denominator remains full exact normalizer. | One organizationally distinct reviewer must bind a verdict to the exact v1.1 body, including the full-denominator firewall and support-respecting regular-conditional-version clarification.
A7: RV-LM011-MAIN | B7: MATH | C7: LCR-DER-033-v1.0 | D7: NEEDS_RECONCILIATION | E7: Verify and register the existing exact technical verdict; perform new mathematics only for missing or changed criteria | F7: https://docs.google.com/document/d/1Tlkrs-WtWJg-OkrUvMIbwei_qi9BCa0-9xfHv4BSuEk/edit | G7: CURRENT v1.0 EXACT BODY REPRODUCED / SAME-LINE CONDITIONAL SYNTHESIS PASS / CURRENT DEPENDENCY GRAPH / OWN EXTERNAL VERDICT AND OPEN COMPONENT PREDICATES REQUIRED | H7: EXTERNAL_REVIEW_OPEN | I7: 2026-07-25T21:12:00Z | J7: Legacy review-routing record; request onset not independently reconstructed | L7: =IF(I7="","",MAX(0,TODAY()-DATE(VALUE(LEFT(I7,4)),VALUE(MID(I7,6,2)),VALUE(MID(I7,9,2))))) -> 60 | M7: =IF(L7="","UNKNOWN",IF(D7="PASS_TECHNICAL","EXTERNAL ONLY",IF(L7>=30,"ESCALATE",IF(L7>=14,"DECOMPOSE",IF(L7>=7,"PRIORITIZE","NEW"))))) -> ESCALATE | N7: OpenAI; exact author session to be disclosed | O7: 17c37fa1da7aa246f3018bd4ecc69b6e7beef5d8a1bda616d250146b3629efa9 | P7: 9721 | Q7: UNASSIGNED | S7: Current exact interfaces compose to imply 1-a_r=O(r^3). | First obtain the open exact component verdicts for LM003, LM004-v1.1, LM006, LM009, LM010-v1.1, LM012-v1.1, and LM013 Carrier-B-v1.1 plus joint stack. Then issue the organizationally distinct final synthesis verdict on the exact 9,721-byte body under current LCR-REQ-053-v1.2, using LCR-REQ-037-v1.0 as the object-level checklist.
A8: RV-LM012-MAIN | B8: MATH | C8: LCR-DER-043-v1.1 | D8: NEEDS_RECONCILIATION | E8: Verify and register the existing exact technical verdict; perform new mathematics only for missing or changed criteria | F8: https://docs.google.com/document/d/1X-46gXEIqZr8JMc458ikHGKtLsQpRIrEgwUknhUd5ig/edit | G8: CONTROLLING DEEP-THRESHOLD SUCCESSOR v1.1 / EXACT BODY VERIFIED SAME-LINE / ORGANIZATIONALLY DISTINCT EXACT-HASH REVIEW OPEN / NONTERMINAL | H8: EXTERNAL_REVIEW_OPEN | I8: 2026-07-26T13:36:00Z | J8: Legacy review-routing record; request onset not independently reconstructed | L8: =IF(I8="","",MAX(0,TODAY()-DATE(VALUE(LEFT(I8,4)),VALUE(MID(I8,6,2)),VALUE(MID(I8,9,2))))) -> 59 | M8: =IF(L8="","UNKNOWN",IF(D8="PASS_TECHNICAL","EXTERNAL ONLY",IF(L8>=30,"ESCALATE",IF(L8>=14,"DECOMPOSE",IF(L8>=7,"PRIORITIZE","NEW"))))) -> ESCALATE | N8: OpenAI; exact author session to be disclosed | O8: 68df32086da07fac8b042789de7a1c280aa2df56885532618c2fcabdb04b9ad4 | P8: 11543 | Q8: UNASSIGNED | S8: Coordinate-typed chart lift, one positive common small-r domain, and deep-threshold sample-event firewall for deterministic capture. | One organizationally distinct reviewer must execute LCR-REQ-045-v1.1 against the v1.1 hash and verify chart identity, deep-saddle threshold placement, common domain, and scaling.
A9: RV-LM013-BOREL-GLOBALIZATION | B9: MATH | C9: LCR-DER-061-v1.1 | D9: NEEDS_RECONCILIATION | E9: Verify and register the existing exact technical verdict; perform new mathematics only for missing or changed criteria | F9: https://docs.google.com/document/d/1c_-wbmoEiwKl4lzpKQFCY5BpdKDP0iYCqPhfEUSFkdk/edit | G9: PARENT EXACT-OBJECT REVIEW SATISFIED / CARRIER A EXACT-HASH APPROVE / CARRIER B v1.1 SAME-LINE PASS / EXTERNAL v1.1 CONVERSION AND JOINT STACK VERDICT OPEN / NONTERMINAL | H9: EXTERNAL_REVIEW_OPEN | I9: 2026-07-26T15:18:00Z | J9: Legacy review-routing record; request onset not independently reconstructed | L9: =IF(I9="","",MAX(0,TODAY()-DATE(VALUE(LEFT(I9,4)),VALUE(MID(I9,6,2)),VALUE(MID(I9,9,2))))) -> 59 | M9: =IF(L9="","UNKNOWN",IF(D9="PASS_TECHNICAL","EXTERNAL ONLY",IF(L9>=30,"ESCALATE",IF(L9>=14,"DECOMPOSE",IF(L9>=7,"PRIORITIZE","NEW"))))) -> ESCALATE | N9: OpenAI; exact author session to be disclosed | O9: 8ec4386fc1214523c98a5ae84acf4f5f64a6601aa2c63728f4382701b82dc3b7 | P9: 8928 | Q9: UNASSIGNED | S9: Countable Borel globalization, selector independence, Borel convergence event, certificate inclusion, and conditional exact Palm admissibility whenever 0<Z<infinity. | Obtain the narrow organizationally distinct Carrier B v1.1 conversion under LS-P01-REQ-002, then issue the repaired joint three-object interface verdict. Do not repeat the satisfied parent or Carrier A reviews.
A10: RV-DQ-005 | B10: MATH | C10: GP-DER/DATA-212 full-matrix exact finite-dimensional base-mass successor | D10: NEEDS_RECONCILIATION | E10: Resolve current exact target/hash and existing verdicts; then perform a bounded nonauthor technical review | F10: Proof https://docs.google.com/document/d/1XPukFF2usb9WyA2bRVvxwKebOxtHakZGJlfRSf7ewds/edit | source https://docs.google.com/document/d/1yaQ8R1OW1t-WJT7JGp3rVco3FQkIYXELshVI6Wt6vUY/edit | result https://docs.google.com/document/d/1mmIwF4m7yoXw2DOnjmdfqiZg36xyYNZX_PuAhMsoT3E/edit | request https://docs.google.com/document/d/1X9nr7tRhGrudpTdS-4QVsGxGoEAjt0OxLI7SEt592kg/edit | G10: OPEN / SUCCESSOR ELIGIBLE / GP-DATA-204 AMEND REQUIRED | OpenAI may reconcile only; organizationally distinct successor-hash review required | H10: LEGACY_PREDICATE_RETAINED | I10: 2026-07-25T16:15:00Z | J10: Dispatch Created UTC; not proof of zero intervening review | L10: =IF(I10="","",MAX(0,TODAY()-DATE(VALUE(LEFT(I10,4)),VALUE(MID(I10,6,2)),VALUE(MID(I10,9,2))))) -> 60 | M10: =IF(L10="","UNKNOWN",IF(D10="PASS_TECHNICAL","EXTERNAL ONLY",IF(L10>=30,"ESCALATE",IF(L10>=14,"DECOMPOSE",IF(L10>=7,"PRIORITIZE","NEW"))))) -> ESCALATE | N10: Disclose exact-object authorship; provider alone is insufficient | O10: UNRESOLVED — bind before review | Q10: UNASSIGNED | S10: Reconstruct and rerun GP-DATA-212; audit the full 9×9 spectral witnesses, direct-sum cross-check, exact nine-coordinate box geometry, derived distance rational, transformed torus reserve, perturbation chain, density lower bound, r_GR=r_D, p_B=10^-48, hashes, and controls; issue PASS / AMEND / FAIL. | Exact source/result roundtrip; execution or independent reconstruction; all 18 full-matrix Sylvester minors; explicit box intervals and distance derivation; periodization and density directions; hostile mutations; no theorem promotion.
A11: RV-DQ-017 | B11: COMPUTE | C11: LS-DATA-013 q0 verifier 1.2.1 hardening successor | D11: NEEDS_RECONCILIATION | E11: Resolve current exact target/hash and existing verdicts; then perform a bounded nonauthor technical review | F11: request https://docs.google.com/document/d/1zB58oOT1tmzzF5TAAlHqA8A1wxznjk2qTYMZ4BzV6Jw/edit | package https://docs.google.com/document/d/1B8_l-jXd5jo5ETMmoF-tMx8PcuwwshAq51KiagHDMp0/edit | audit https://docs.google.com/document/d/1B7YRIniaDmiXdKVSGLHy-S_y_hwQ7Yt5MNIx3zameCo/edit | G11: OPEN / EXTERNAL-FAMILY ELIGIBLE / NONCANONICAL ONLY | Non-OpenAI verifier/security reviewer or qualified human may earn successor-review credit; OpenAI logistics only | H11: LEGACY_PREDICATE_RETAINED | I11: 2026-07-26T00:02:00Z | J11: Dispatch Created UTC; not proof of zero intervening review | L11: =IF(I11="","",MAX(0,TODAY()-DATE(VALUE(LEFT(I11,4)),VALUE(MID(I11,6,2)),VALUE(MID(I11,9,2))))) -> 59 | M11: =IF(L11="","UNKNOWN",IF(D11="PASS_TECHNICAL","EXTERNAL ONLY",IF(L11>=30,"ESCALATE",IF(L11>=14,"DECOMPOSE",IF(L11>=7,"PRIORITIZE","NEW"))))) -> ESCALATE | N11: Disclose exact-object authorship; provider alone is insufficient | O11: UNRESOLVED — bind before review | Q11: UNASSIGNED | S11: Execute LS-REQ-014 against source SHA 5202c5fa33b1f08d502220943443573cc8c8e3a31682e6f3079443647fe0f6b9. Verify duplicate-key rejection at byte boundary, empty-route rejection, structural cycle invalidity, predecessor compatibility, 12 original tests, nine CL mutations, root-report equality, exact report/receipt identities, and active-file immutability. | Source and output capsule hashes reproduced; machine SHA 65af5209...2219; report SHA 5442f314...4b01; 12/12 + 9/9 pass; all cycles invalid; zero roots promotable unchanged; explicit APPROVE / AMEND / FAIL; no installation.
A12: RV-DQ-020 | B12: COMPUTE | C12: GP-DATA-218 stable-key guarded register-write reference and sandbox qualification | D12: NEEDS_RECONCILIATION | E12: Resolve current exact target/hash and existing verdicts; then perform a bounded nonauthor technical review | F12: request https://docs.google.com/document/d/1fVXf0h33ZKHqklydALKXCXB65gPKJZSdILew1Genmeg/edit | proof https://docs.google.com/document/d/1pzgS54wGicsakLmpL53m2Jf5-YLAlfNfBIDXRgWUvWw/edit | controlling package https://docs.google.com/document/d/1EktScfxgfH9OkeosIS8_6h1flyQmHgnCs142iFvQcRc/edit | supplement https://docs.google.com/document/d/1kPR2Fsh47eT73WHvyT_dv90hRQxjCNaVlU37LyanU_A/edit | G12: OPEN / EXTERNAL-FAMILY ELIGIBLE / SANDBOX-ONLY | Non-OpenAI verifier/security reviewer or qualified human may earn successor-review credit; OpenAI logistics only | H12: LEGACY_PREDICATE_RETAINED | I12: 2026-07-26T02:29:00Z | J12: Dispatch Created UTC; not proof of zero intervening review | L12: =IF(I12="","",MAX(0,TODAY()-DATE(VALUE(LEFT(I12,4)),VALUE(MID(I12,6,2)),VALUE(MID(I12,9,2))))) -> 59 | M12: =IF(L12="","UNKNOWN",IF(D12="PASS_TECHNICAL","EXTERNAL ONLY",IF(L12>=30,"ESCALATE",IF(L12>=14,"DECOMPOSE",IF(L12>=7,"PRIORITIZE","NEW"))))) -> ESCALATE | N12: Disclose exact-object authorship; provider alone is insufficient | O12: UNRESOLVED — bind before review | Q12: UNASSIGNED | S12: Execute GP-REQ-219 against controlling source SHA 199b7ce57f065b54b2a8f160e89fe38ef90f3118408d2fbb5eeca8a601a8855a. Reproduce the package; audit fresh sheet-title resolution, unique primary-key location, stale-row and stale-grid resistance, preconditions, patch scope, post-write verification, receipts, and all six isolated target schemas including Duplicate Flags. Use DQ018-AUD-001 only as same-family mutation and schema-coverage guidance. | Three controlling raw identities reproduced; R0-R15 plus R12A/R13A complete; M1-M14 attempted; 14/14 controlling reference checks, 20/20 supplement tests, and six-schema Drive correspondence verified; explicit APPROVE / AMEND / FAIL / CANNOT VERIFY verdict; no production installation.
A13: RV-DQ-023 | B13: MATH | C13: LS-DER-021 TB-G2 compact-mark all-typed contact-intensity candidate | D13: NEEDS_RECONCILIATION | E13: Resolve current exact target/hash and existing verdicts; then perform a bounded nonauthor technical review | F13: corrected work order https://docs.google.com/document/d/17jWejscjJpJrkml5bXQbWn8nvTeMRwcW_5-V32lJfWU/edit | parent request https://docs.google.com/document/d/12Y2SurB-s-V-UqkmJih-Lu2k3gTdYLuLZnUTCs6EZ7o/edit | parent theorem https://docs.google.com/document/d/16dSMQF3nbRcx93feO8vJzdnT8wDQvO-p6zViPtyUazw/edit | companion https://docs.google.com/document/d/1AUEXzPfbZsdtArlkHNhIUK4hbHqg8ATbb5M99Ex57HU/edit | reconciliation https://docs.google.com/document/d/1oGWql4Hez1BGDfUVl1USgZ2K3--DO5D2XGmcEgKwiSo/edit | erratum https://docs.google.com/document/d/1qYErvvtnUYio27BC7n6BJCnBw-GgC_dR3Y6eguUD5KA/edit | G13: OPEN / PRIOR ANTHROPIC SCOPED REVIEW EXISTS / THIRD-FAMILY EXACT-HASH AND UNIFORM-ENVELOPE GATE OPEN / DQ-053 COMPANION REVIEW OPEN | One Anthropic lineage supplies scoped partial TB-G2 evidence; OpenAI LS-DER-032 supplies zero-credit same-family interface proof; DQ-023’s next independent path must be neither OpenAI nor Anthropic. | H13: LEGACY_PREDICATE_RETAINED | I13: 2026-07-26T13:35:00Z | J13: Dispatch Created UTC; not proof of zero intervening review | L13: =IF(I13="","",MAX(0,TODAY()-DATE(VALUE(LEFT(I13,4)),VALUE(MID(I13,6,2)),VALUE(MID(I13,9,2))))) -> 59 | M13: =IF(L13="","UNKNOWN",IF(D13="PASS_TECHNICAL","EXTERNAL ONLY",IF(L13>=30,"ESCALATE",IF(L13>=14,"DECOMPOSE",IF(L13>=7,"PRIORITIZE","NEW"))))) -> ESCALATE | N13: Disclose exact-object authorship; provider alone is insufficient | O13: UNRESOLVED — bind before review | Q13: UNASSIGNED | S13: Execute LS-DER-021-REVIEW-002 against LS-DER-021. Reproduce the exact body, adjudicate the six-pin eigenfloor, uniform density/moment/integrability envelope, equations (15),(16),(23), q-behaviour, and full same-law normalizer; reconcile separately with LS-DER-032/DQ-053. | Capability and canary pass; OP-PROT-017 body reproduced; blind method reservation frozen; mutations M1–M9 completed; reviewer is neither OpenAI nor Anthropic; exact scoped verdict and downstream/non-effect statement returned; no first-review claim.
A14: RV-DQ-027 | B14: COMPUTE | C14: TRC-EC020-v0.4 derived carrier successors and GP-DATA-233 validator | D14: NEEDS_RECONCILIATION | E14: Resolve current exact target/hash and existing verdicts; then perform a bounded nonauthor technical review | F14: https://docs.google.com/document/d/1Flv8fSNCQmiN1FJ05quf1dsfiGRTKlh5hZODCFvj1VQ/edit | G14: OPEN / EXTERNAL-FAMILY ELIGIBLE / EXACT-HASH PACKAGE REVIEW READY / ZERO-CREDIT GP PREFLIGHT PASS | Non-OpenAI package reviewer may earn one package-review independence credit; OpenAI preflight supplies zero credit. | H14: LEGACY_PREDICATE_RETAINED | I14: 2026-07-26T14:42:24Z | J14: Dispatch Created UTC; not proof of zero intervening review | L14: =IF(I14="","",MAX(0,TODAY()-DATE(VALUE(LEFT(I14,4)),VALUE(MID(I14,6,2)),VALUE(MID(I14,9,2))))) -> 59 | M14: =IF(L14="","UNKNOWN",IF(D14="PASS_TECHNICAL","EXTERNAL ONLY",IF(L14>=30,"ESCALATE",IF(L14>=14,"DECOMPOSE",IF(L14>=7,"PRIORITIZE","NEW"))))) -> ESCALATE | N14: Disclose exact-object authorship; provider alone is insufficient | O14: UNRESOLVED — bind before review | Q14: UNASSIGNED | S14: Execute GP-REQ-235 R0-R10 as the permitted outside reviewer. The GP preflight reproduced all exact hashes, the validator receipt, nine leaves, live IDs/MIMEs, topology, and 10 fail-closed controls; independently adjudicate three Drive-title mismatches. | Reproduce SHA-256 values 0c19d4bb...20a95, 23861601...77b1, 466d544d...ddb1 and validator source e8d51d76...d64b8; decide whether the three title mismatches are nonmaterial or require a numbered successor; issue the required scoped verdict. Root NONE; SEALED NO.
A15: RV-DQ-035 | B15: MATH | C15: LS-DER-026 TB-G4 full-kappa selected near-diagonal tail theorem | D15: NEEDS_RECONCILIATION | E15: Resolve current exact target/hash and existing verdicts; then perform a bounded nonauthor technical review | F15: request https://docs.google.com/document/d/1Y99z0sQWMDweMCdHzWAYgoRTuysmkiQwQFPLGDs49ho/edit | candidate https://docs.google.com/document/d/1kSk34R28YpUdPmFjrLam1yDfOrcghyWJhTE_WbzqDGE/edit | G15: OPEN / EXTERNAL-FAMILY ELIGIBLE / EXACT-HASH REVIEW READY | Non-OpenAI Gaussian-analysis reviewer or qualified human may earn organizational-independence credit; OpenAI logistics only | H15: LEGACY_PREDICATE_RETAINED | I15: 2026-07-26T15:25:52Z | J15: Dispatch Created UTC; not proof of zero intervening review | L15: =IF(I15="","",MAX(0,TODAY()-DATE(VALUE(LEFT(I15,4)),VALUE(MID(I15,6,2)),VALUE(MID(I15,9,2))))) -> 59 | M15: =IF(L15="","UNKNOWN",IF(D15="PASS_TECHNICAL","EXTERNAL ONLY",IF(L15>=30,"ESCALATE",IF(L15>=14,"DECOMPOSE",IF(L15>=7,"PRIORITIZE","NEW"))))) -> ESCALATE | N15: Disclose exact-object authorship; provider alone is insufficient | O15: UNRESOLVED — bind before review | Q15: UNASSIGNED | S15: Execute LS-REQ-022 against LS-DER-026 frozen body 11,725 bytes / SHA-256 e4d8094ed1bfc9f9cc7491f13efd5cc5294ba3b5f4fbd4bc8bbba33dd1a2ab5d. Reconstruct corrected-pin decay, determinant moments, compact selection portability, cutoff, and dominated convergence. | Hash reproduced; R0-R17 complete; M1-M16 attempted; explicit APPROVE / CLARIFY / AMEND / FAIL / CANNOT VERIFY verdict; exact near-diagonal scope; no full-density promotion.
A16: RV-DQ-038 | B16: MATH | C16: LS-DER-022 TB-G3 exact actual-selection reduction and kappa-normalized capture | D16: NEEDS_RECONCILIATION | E16: Resolve current exact target/hash and existing verdicts; then perform a bounded nonauthor technical review | F16: request https://docs.google.com/document/d/10ai9iyt83V3wwkasqOzifVuw0xES5G4dAUTJJwq_UHo/edit | candidate https://docs.google.com/document/d/1rwKtmy2vnXTYfp0jFrf5Ca1jaBj0DYr7Uf5-Pui33Uo/edit | Anthropic review https://docs.google.com/document/d/1o0aeX97l_f6Z0fRc9yTgw0TY_pYcWHS7RTB8YxeanDw/edit | reconciliation https://docs.google.com/document/d/1oGWql4Hez1BGDfUVl1USgZ2K3--DO5D2XGmcEgKwiSo/edit | identity https://docs.google.com/document/d/1J7ZI-VzAyBQjsa8aKGcgySFI1y2Y23SYi6_tuv8NTBg/edit | G16: OPEN / ONE ANTHROPIC PARTIAL VERDICT RECEIVED / EXACT-OBJECT COMPLETION STILL REQUIRED | One Anthropic lineage approves the safe probability bridge at mathematical core; exact hash and lower-layer fixed-mark/import scope remain incomplete | H16: LEGACY_PREDICATE_RETAINED | I16: 2026-07-26T15:47:00Z | J16: Dispatch Created UTC; not proof of zero intervening review | L16: =IF(I16="","",MAX(0,TODAY()-DATE(VALUE(LEFT(I16,4)),VALUE(MID(I16,6,2)),VALUE(MID(I16,9,2))))) -> 59 | M16: =IF(L16="","UNKNOWN",IF(D16="PASS_TECHNICAL","EXTERNAL ONLY",IF(L16>=30,"ESCALATE",IF(L16>=14,"DECOMPOSE",IF(L16>=7,"PRIORITIZE","NEW"))))) -> ESCALATE | N16: Disclose exact-object authorship; provider alone is insufficient | O16: UNRESOLVED — bind before review | Q16: UNASSIGNED | S16: Execute LS-REQ-018 against LS-DER-022 frozen body 21,932 bytes / SHA-256 e5a61739bf09c1972edeb39e683c38da4adbf387c95d65aadf979b84a9568aaf. Verify p=a q_adj+eta, safe complement inequality, fixed-mark composition, positive-time kappa normalization, compact Gaussian block, and exact residual blockers. | Hash reproduced; packet R1-R15 and M1-M12 complete; explicit APPROVE / CLARIFY / AMEND / FAIL / CANNOT VERIFY verdict; exact reduction scope; no dependency or Theorem B promotion.
A17: RV-DQ-053 | B17: MATH | C17: LS-DER-032 TB-G2 uniform six-pin covariance and conditional-moment interface | D17: NEEDS_RECONCILIATION | E17: Resolve current exact target/hash and existing verdicts; then perform a bounded nonauthor technical review | F17: request https://docs.google.com/document/d/1sAkJPHfdkUhq-SeY6mpB2bkqCY54vtWKEnVXM52bNUA/edit | companion https://docs.google.com/document/d/1AUEXzPfbZsdtArlkHNhIUK4hbHqg8ATbb5M99Ex57HU/edit | parent https://docs.google.com/document/d/16dSMQF3nbRcx93feO8vJzdnT8wDQvO-p6zViPtyUazw/edit | G17: OPEN / EXTERNAL-FAMILY ELIGIBLE / EXACT-HASH REVIEW READY | Non-OpenAI reviewer or qualified human may earn object-specific review credit; Anthropic remains its existing single lineage | H17: LEGACY_PREDICATE_RETAINED | I17: 2026-07-26T19:30:00Z | J17: Dispatch Created UTC; not proof of zero intervening review | L17: =IF(I17="","",MAX(0,TODAY()-DATE(VALUE(LEFT(I17,4)),VALUE(MID(I17,6,2)),VALUE(MID(I17,9,2))))) -> 59 | M17: =IF(L17="","UNKNOWN",IF(D17="PASS_TECHNICAL","EXTERNAL ONLY",IF(L17>=30,"ESCALATE",IF(L17>=14,"DECOMPOSE",IF(L17>=7,"PRIORITIZE","NEW"))))) -> ESCALATE | N17: Disclose exact-object authorship; provider alone is insufficient | O17: UNRESOLVED — bind before review | Q17: UNASSIGNED | S17: Execute LS-REQ-028 against LS-DER-032 frozen body 12,106 bytes / SHA-256 3531e6e5c569319388964429d36af8de0ca8768668ac43a53b5a5b2490fd4dba. Reconstruct Fourier symbols, lattice rigidity, uniform eigenfloors, density bounds, regression moments, Q nondegeneracy, and the expectation-limit interface. | Hash reproduced; R0-R12 and M1-M10 completed; explicit scoped verdict, source exposure, and lineage; no automatic LS-DER-021 approval, DQ-023 closure, or Theorem B promotion.
A18: RV-DQ-057 | B18: MATH | C18: LS-DER-036-v1.1 fixed-compact exact Palm O(r^3) loop successor | D18: NEEDS_RECONCILIATION | E18: Resolve current exact target/hash and existing verdicts; then perform a bounded nonauthor technical review | F18: review https://docs.google.com/document/d/19RaCdwEHAVRjOynksS2umRRV7luCBfvAlWlHXVi50oo/edit | successor https://docs.google.com/document/d/1f_bqwcWGp9sS13-v4qHdzNROKx2hzvAlDTTl-skco-Q/edit | predecessor verdict https://docs.google.com/document/d/1zMq504Z2iW4cDr220n8D5sc66kMzwDGGqNMrlwY8f6U/edit | G18: OPEN / NUMBERED SUCCESSOR PUBLISHED / EXACT-HASH REVIEW READY / DQ-023 AND DQ-028 OPEN | An eligible successor reviewer may qualify v1.1 without transferring or multiplying predecessor Anthropic credit | H18: LEGACY_PREDICATE_RETAINED | I18: 2026-07-27T17:52:00Z | J18: Dispatch Created UTC; not proof of zero intervening review | L18: =IF(I18="","",MAX(0,TODAY()-DATE(VALUE(LEFT(I18,4)),VALUE(MID(I18,6,2)),VALUE(MID(I18,9,2))))) -> 58 | M18: =IF(L18="","UNKNOWN",IF(D18="PASS_TECHNICAL","EXTERNAL ONLY",IF(L18>=30,"ESCALATE",IF(L18>=14,"DECOMPOSE",IF(L18>=7,"PRIORITIZE","NEW"))))) -> ESCALATE | N18: Disclose exact-object authorship; provider alone is insufficient | O18: UNRESOLVED — bind before review | Q18: UNASSIGNED | S18: Execute LS-REQ-032: reconstruct fixed-chart Gaussian regression, Dudley/Borell concentration, boundary r-power ledger, outward corridor, one-branch logic, and corrected TB-G3B reduction. | Reproduce 16,856 bytes / SHA-256 3416ddeebacd071f316a1e281aa3df2e99cf1e4965c1eb8bac203d23b6eb05b3; complete R0-R20 and M1-M18; state C1-C4 disposition and dependency firewall.
A19: RV-DQ-061 | B19: MATH | C19: LS-DER-038 corrected compact actual-selection and specific minus-one-third component successor | D19: NEEDS_RECONCILIATION | E19: Resolve current exact target/hash and existing verdicts; then perform a bounded nonauthor technical review | F19: request https://docs.google.com/document/d/1HLgGIYkveWdh7SxzkDaQUJ2xRP3LapmWLQrAeMvtHHw/edit | candidate https://docs.google.com/document/d/1c8eP9TWsgGoLdm393k7QUATzCH16oCThcuB-SH4IriY/edit | predecessor verdict https://docs.google.com/document/d/1LU4Mxm3Gmh2Vhqsdemt7XDjwnHVE1ZCMMKcTu_YNqwU/edit | G19: OPEN / EXTERNAL-FAMILY ELIGIBLE / EXACT-HASH REVIEW READY | A reviewer outside OpenAI may earn exact-object review credit; existing Anthropic synthesis lineage counts once | H19: LEGACY_PREDICATE_RETAINED | I19: 2026-07-28T06:23:35Z | J19: Dispatch Created UTC; not proof of zero intervening review | L19: =IF(I19="","",MAX(0,TODAY()-DATE(VALUE(LEFT(I19,4)),VALUE(MID(I19,6,2)),VALUE(MID(I19,9,2))))) -> 57 | M19: =IF(L19="","UNKNOWN",IF(D19="PASS_TECHNICAL","EXTERNAL ONLY",IF(L19>=30,"ESCALATE",IF(L19>=14,"DECOMPOSE",IF(L19>=7,"PRIORITIZE","NEW"))))) -> ESCALATE | N19: Disclose exact-object authorship; provider alone is insufficient | O19: UNRESOLVED — bind before review | Q19: UNASSIGNED | S19: Execute LS-REQ-033 against LS-DER-038. Verify corrected event algebra, L_same import, compact selection, unit multiplicity, radial Jacobian, specific coefficient, and total factor 576. | Reproduce 10,410 bytes / SHA-256 5fd2413c52eac9538f85dba3ecaad68861c23f31a03e4a8b766c9914e518b7e5; complete R0-R17 and M1-M18; no full-density or theorem promotion.
A20: RV-DQ-096 | B20: MATH | C20: LS-REQ-037 review of LS-DER-064/068 and LS-DER-065/067/069 | D20: NEEDS_RECONCILIATION | E20: Resolve current exact target/hash and existing verdicts; then perform a bounded nonauthor technical review | F20: https://docs.google.com/document/d/1KGpfr5lWfTq7evVi2_inA0qIrA9TPnsu4GlBddRhsWo/edit | G20: READY / UNCLAIMED / EXECUTE AFTER RESET | Packet itself creates zero independence; Anthropic verdict required | H20: LEGACY_PREDICATE_RETAINED | I20: 2026-07-28T20:58:00Z | J20: Dispatch Created UTC; not proof of zero intervening review | L20: =IF(I20="","",MAX(0,TODAY()-DATE(VALUE(LEFT(I20,4)),VALUE(MID(I20,6,2)),VALUE(MID(I20,9,2))))) -> 57 | M20: =IF(L20="","UNKNOWN",IF(D20="PASS_TECHNICAL","EXTERNAL ONLY",IF(L20>=30,"ESCALATE",IF(L20>=14,"DECOMPOSE",IF(L20>=7,"PRIORITIZE","NEW"))))) -> ESCALATE | N20: Disclose exact-object authorship; provider alone is insufficient | O20: UNRESOLVED — bind before review | Q20: UNASSIGNED | S20: Attack analytic Hessian/image-tail proof and the full side-24 G1-G7 selected-persistence composition; issue strict terminal verdict. | Frozen packet 7,013 bytes / SHA-256 e5ae1b6d55539a7b5dd4b90e6e38a48b8402437bc7d7af9f5a884f163cf06737.
A21: RV-RN3 | B21: MATH | C21: RN3 joint far-zone fixed r=1/20 | D21: READY | E21: Replay RN3 bundle and audit every uniform bound; RN5 report-level crosswalk explains distinct kappa majorants and scopes the near-moment defect | F21: https://drive.google.com/file/d/1f0EBsq6UIZ0jDCABT251TTNEWYCVA0FO/view | G21: Author replay only; alternative Anthropic far-zone work is not a review | H21: EXTERNAL_REVIEW_OPEN | I21: 2026-09-17T16:25:48.473074Z | J21: New R17 request | L21: =IF(I21="","",MAX(0,TODAY()-DATE(VALUE(LEFT(I21,4)),VALUE(MID(I21,6,2)),VALUE(MID(I21,9,2))))) -> 6 | M21: =IF(L21="","UNKNOWN",IF(D21="PASS_TECHNICAL","EXTERNAL ONLY",IF(L21>=30,"ESCALATE",IF(L21>=14,"DECOMPOSE",IF(L21>=7,"PRIORITIZE","NEW"))))) -> NEW | N21: OpenAI / RN3-20260917-b9c2 | O21: 0c9446b7cb49e6e1e45e43f84bb72ce680f022882e225fdff61c8e6edede1373 | P21: 12956 | Q21: UNASSIGNED | S21: Fixed r, fixed axis, side-24; near annulus and all-small-r remain open. Bundle https://drive.google.com/file/d/1z_zNdgxtbs7XWxLu56HN8_QbVXxdmMMq/view
A22: RV-RN-ALIGN | B22: MATH | C22: CL-RNU-003 and RN3 exact-object crosswalk | D22: AMEND | E22: Correct near-moment claim and complete spatial cover; locate named CL v5 archive / rnu_t4.py / rnu_spine.py before executable crosswalk | F22: https://drive.google.com/file/d/1aCa-QG9CSrNUB9SUFKISifghSf-41fRy/view | G22: Report-level comparison complete; wrong near determinant moment proved. No CL executable replay; RN3 author lineage. | H22: AUTHOR_SIDE / ZERO ORG CREDIT | I22: 2026-09-17T16:25:48.473074Z | J22: New R17 request | K22: 2026-09-17T17:19:16.450Z | L22: =IF(I22="","",MAX(0,TODAY()-DATE(VALUE(LEFT(I22,4)),VALUE(MID(I22,6,2)),VALUE(MID(I22,9,2))))) -> 6 | M22: =IF(L22="","UNKNOWN",IF(D22="PASS_TECHNICAL","EXTERNAL ONLY",IF(L22>=30,"ESCALATE",IF(L22>=14,"DECOMPOSE",IF(L22>=7,"PRIORITIZE","NEW"))))) -> NEW | N22: Anthropic CL-RNU-003; OpenAI RN3 | O22: RN3 0c9446b7cb49e6e1e45e43f84bb72ce680f022882e225fdff61c8e6edede1373; CL 59b8f002f1b1e81e7829416baf16ef1d84b1326d4b3b4604b833e5a55a9d6d53 | Q22: ROUND5 / OpenAI / author-side | R22: https://drive.google.com/file/d/1LtnvNd0vAW-y3pzbyHLjgtF7Uw5sTph5/view | S22: Different kappa majorants are not conflicting heads. CL report Section 3 on scoped hold. CANNOT_VERIFY current CL executable/checkpoint identity: named code/archive not found in bounded source lookups.
A23: RV-P15 | B23: MATH | C23: P15-A/B/C/D structural localization | D23: READY | E23: Bind archive and exact proof paths, then execute R1–R8 packet; split into four scoped reviews | F23: https://drive.google.com/file/d/1mLizXdV8guLCJoJGa7iyvjDc3C1XElxr/view | G23: Author-side complete; external reviews 0 in current state | H23: EXTERNAL_REVIEW_OPEN | I23: 2026-09-17T16:25:48.473074Z | J23: New R17 request | L23: =IF(I23="","",MAX(0,TODAY()-DATE(VALUE(LEFT(I23,4)),VALUE(MID(I23,6,2)),VALUE(MID(I23,9,2))))) -> 6 | M23: =IF(L23="","UNKNOWN",IF(D23="PASS_TECHNICAL","EXTERNAL ONLY",IF(L23>=30,"ESCALATE",IF(L23>=14,"DECOMPOSE",IF(L23>=7,"PRIORITIZE","NEW"))))) -> NEW | N23: Author lineage to be read from exact archive | O23: UNRESOLVED — archive manifest required | Q23: UNASSIGNED | S23: No unrestricted prize closure; current state https://drive.google.com/file/d/1r8weyHObFfHAp-_PfI8mlSXPZQC8Zoh1/view
A24: RV-H5-REPAIR | B24: COMPUTE | C24: H5 corrected-kernel full consumer replay | D24: AMEND | E24: Replay all affected upper/lower certificate consumers against the repaired kernel before certification | F24: https://drive.google.com/file/d/1qtuFKUR0SsX3aeB_uI08b2sJw0DX2EOL/view | G24: Defect and one-box repair replay documented; full cover remains open | H24: REVIEW_AFTER_FULL_REPLAY | I24: 2026-09-17T16:25:48.473074Z | J24: New R17 consolidated request | L24: =IF(I24="","",MAX(0,TODAY()-DATE(VALUE(LEFT(I24,4)),VALUE(MID(I24,6,2)),VALUE(MID(I24,9,2))))) -> 6 | M24: =IF(L24="","UNKNOWN",IF(D24="PASS_TECHNICAL","EXTERNAL ONLY",IF(L24>=30,"ESCALATE",IF(L24>=14,"DECOMPOSE",IF(L24>=7,"PRIORITIZE","NEW"))))) -> NEW | N24: Multiple legacy authors; repaired candidate OpenAI | O24: See Quarantine Index: 11 archive-member hashes | Q24: UNASSIGNED | S24: No H5 certificate chain may consume signed odd-frequency or missing denominator-tail bounds without replay.
A25: RV-OPS-R17 | B25: OPS | C25: OP-PROT-019-v1.1 implementation | D25: READY | E25: Challenge stale handoff, same-family coauthor, publication-race and restoration cases using bundled tests | F25: https://drive.google.com/file/d/1hBph5Fpxd5dVrolNkvzU8nb7xpxUiUdc/view | G25: Author-side implementation; not independently reviewed | H25: EXTERNAL_REVIEW_OPEN | I25: 2026-09-17T16:25:48.473074Z | J25: New R17 request | L25: =IF(I25="","",MAX(0,TODAY()-DATE(VALUE(LEFT(I25,4)),VALUE(MID(I25,6,2)),VALUE(MID(I25,9,2))))) -> 6 | M25: =IF(L25="","UNKNOWN",IF(D25="PASS_TECHNICAL","EXTERNAL ONLY",IF(L25>=30,"ESCALATE",IF(L25>=14,"DECOMPOSE",IF(L25>=7,"PRIORITIZE","NEW"))))) -> NEW | N25: OpenAI / OPS4-20260917-b9c2 | O25: 04987ba47b58be623a3b2a5a8a21236f43d4393cc04009e87f4a62b59a787390 | P25: 14073 | Q25: UNASSIGNED | S25: Cooperative conflict detection, not deployed transactional locking.
A26: RV-RN5-MOMENT-REPAIR | B26: MATH / COMPUTE | C26: RN5 corrected moment and local spatial-box candidate | D26: READY | E26: Execute R1–R10 in bundle; reconstruct Holder, L2 Taylor remainders and marginal whitening; then extend complete near cover | F26: https://drive.google.com/file/d/1LtnvNd0vAW-y3pzbyHLjgtF7Uw5sTph5/view | G26: OpenAI author-side proof/replay; 66 checks; no independent review yet | H26: EXTERNAL_REVIEW_OPEN | I26: 2026-09-17T17:19:16.450Z | J26: New exact RN5 candidate; parent near-annulus remains unresolved | L26: =IF(I26="","",MAX(0,TODAY()-DATE(VALUE(LEFT(I26,4)),VALUE(MID(I26,6,2)),VALUE(MID(I26,9,2))))) -> 6 | M26: =IF(L26="","UNKNOWN",IF(D26="PASS_TECHNICAL","EXTERNAL ONLY",IF(L26>=30,"ESCALATE",IF(L26>=14,"DECOMPOSE",IF(L26>=7,"PRIORITIZE","NEW"))))) -> NEW | N26: OpenAI / ROUND5-20260917-b9c2 | O26: ac89f60b8206bfe011e6c2bc653e7acb39bc83a55c2a2c8fd1e17fd70c6c0383 | P26: 13725 | Q26: UNASSIGNED | S26: 65 exact spatial points with complete mark caps; 10 spatial boxes. No annulus cover, no all-small-r extension, no external acceptance. Bundle https://drive.google.com/file/d/1g5UP_KYlvPmx7LFwjGk6qK5QZLnL1hLj/view
A27: RV-HG-ENVELOPE-20260919-v1 | B27: MATH / COMPUTE | C27: HG-GLOBAL-ENVELOPE-20260919-v1 | D27: READY | E27: Review Hermite normalization and derivative identity; even/odd monomial bounds and two-axis product; interval containment and infinite-shell tail; replay 66 exact cases and negative controls; confirm scope and review flags. | F27: https://drive.google.com/file/d/1pWBlanUuRBPVSrrbSd4XDUxIcX0gU8va/view?usp=drivesdk | G27: OpenAI author proof/checks only; no nonauthor technical review | H27: REVIEW OPEN / 0 INDEPENDENCE CREDIT | I27: 2026-09-20T00:24:04.500427+00:00 | J27: New request for this exact 3641-byte author candidate; no prior review age reset. | L27: =IF(I27="","",MAX(0,TODAY()-DATE(VALUE(LEFT(I27,4)),VALUE(MID(I27,6,2)),VALUE(MID(I27,9,2))))) -> 3 | M27: =IF(L27="","UNKNOWN",IF(D27="PASS_TECHNICAL","EXTERNAL ONLY",IF(L27>=30,"ESCALATE",IF(L27>=14,"DECOMPOSE",IF(L27>=7,"PRIORITIZE","NEW"))))) -> NEW | N27: OpenAI / Codex / task 01a0bbb5-2fcb-77f0-b78b-4d220ddd7ab2 | O27: 8c0dccdfd177b7ae03a0edd62f92b330825469a9e991d33d2226eb62cfd6083e | P27: 3641 | Q27: UNASSIGNED | S27: Bundle https://drive.google.com/file/d/1WqIeKAosnVrdco7DNemuEgUKRrLVCd9D/view?usp=drivesdk; Git 508ae7e20301df57da0045b13bc7ed9eb0b67ead. Plane derivative envelope and conditional axial-box tails only; no full 24-jet,six-pin,band certificate or obligation closure.
A28: RV-RN-AFFINE-MOMENTS-20260920-v1 | B28: MATH / COMPUTE | C28: RN-AFFINE-MOMENTS-20260920-v1 | D28: READY | E28: Reconstruct correlated affine Gaussian recurrence, noncentral trace formula, PSD singular cases and Bernstein full-interval enclosure; check RN5 coordinate order/common conditioning; replay negative controls and disclosed evaluation overlap. No field or status inference. | F28: https://drive.google.com/file/d/1RXhWblyRQYpadj6X7e3IZTmNO4JXXgo3/view | G28: Author verification plus exposed same-provider context review; modulo35 evaluation alias found and corrected. No independent approval. | H28: REVIEW OPEN / 0 INDEPENDENCE CREDIT | I28: 2026-09-20T01:39:25.155338+00:00 | J28: New exact7394-byte candidate request; previous Hermite request unchanged. | L28: =IF(I28="","",MAX(0,TODAY()-DATE(VALUE(LEFT(I28,4)),VALUE(MID(I28,6,2)),VALUE(MID(I28,9,2))))) -> 3 | M28: =IF(L28="","UNKNOWN",IF(D28="PASS_TECHNICAL","EXTERNAL ONLY",IF(L28>=30,"ESCALATE",IF(L28>=14,"DECOMPOSE",IF(L28>=7,"PRIORITIZE","NEW"))))) -> NEW | N28: OpenAI / Codex / task01a0bbb5-2fcb-77f0-b78b-4d220ddd7ab2 | O28: 4c1803f23e5bbb02baf0a5f5dec6bd4c00d5c580fdffce05180619e7d9158520 | P28: 7394 | Q28: UNASSIGNED
A29: RV-RN-INTERVAL-FAMILIES-20260920-v1 | B29: MATH / COMPUTE | C29: RN-INTERVAL-FAMILIES-20260920-v1 | D29: READY | E29: Reconstruct coefficient interval inclusion, all-PSD sufficient test versus PSD-member quantifier, exact singleton recovery and full Bernstein mark subdivisions. Replay independent Gaussian expansion and covariance/midpoint/mixed-law controls. No actual field identification or spatial-cover inference. | F29: https://drive.google.com/file/d/1r5_R5VoKM10-7eofPwGa_yHuxTAS7S2q/view | G29: Author verification plus exposed same-provider bounded source/code review. Frozen review versions and later changes disclosed; no independent approval. | H29: REVIEW OPEN / 0 INDEPENDENCE CREDIT | I29: 2026-09-20T02:39:50.562453+00:00 | J29: New exact8330-byte interval-family candidate request; prior affine moment request unchanged. | L29: =IF(I29="","",MAX(0,TODAY()-DATE(VALUE(LEFT(I29,4)),VALUE(MID(I29,6,2)),VALUE(MID(I29,9,2))))) -> 3 | M29: =IF(L29="","UNKNOWN",IF(D29="PASS_TECHNICAL","EXTERNAL ONLY",IF(L29>=30,"ESCALATE",IF(L29>=14,"DECOMPOSE",IF(L29>=7,"PRIORITIZE","NEW"))))) -> NEW | N29: OpenAI / Codex / task01a0bbb5-2fcb-77f0-b78b-4d220ddd7ab2 | O29: 0b53ae366eae2b603811f4eb02b09fa44abc220be442419a6801c6349d53adff | P29: 8330 | Q29: UNASSIGNED
A30: RV-RESEARCH-EXECUTION-CERTIFICATES-20260920-v1 | B30: MATH / COMPUTE / FORMAL | C30: RESEARCH-EXECUTION-CERTIFICATES-20260920-v1 | D30: READY | E30: Review exact Gaussian recurrence and interval inclusion, PSD quantifiers, complete Bernstein coverage, LPW parent versus conditional law and radius imports. Inspect recovered Lean statements and sole noncomputable repair; verify receipt completeness and mutation controls. Actual field and analytic premises remain separate. | F30: https://drive.google.com/file/d/1NmwwIUUfIgVepvWjjSaPtLisJar7dpJu/view | G30: Author verification and same-provider coauthor probes. RN malformed/correlated controls, LPW original replay and recovered Lean build disclosed. No independent approval. | H30: REVIEW OPEN / 0 INDEPENDENCE CREDIT | I30: 2026-09-20T03:49:26.405969+00:00 | J30: New exact candidate combining executable scoped results; earlier RN review requests remain unchanged. | L30: =IF(I30="","",MAX(0,TODAY()-DATE(VALUE(LEFT(I30,4)),VALUE(MID(I30,6,2)),VALUE(MID(I30,9,2))))) -> 3 | M30: =IF(L30="","UNKNOWN",IF(D30="PASS_TECHNICAL","EXTERNAL ONLY",IF(L30>=30,"ESCALATE",IF(L30>=14,"DECOMPOSE",IF(L30>=7,"PRIORITIZE","NEW"))))) -> NEW | N30: OpenAI / Codex / task 01a0bbb5-2fcb-77f0-b78b-4d220ddd7ab2 | O30: dc84d820053832437577dfc4a5254031fb58eef521b59f36ad10f77c024e7465 | P30: 33105 | Q30: UNASSIGNED | S30: RN actual field/spatial cover, LPW analytic imports, lost GP-FOR-001 recovery and independent statement/scope review remain open.
A31: RV-RN-SIDE24-POINT-LAW-20260920-v1 | B31: MATH / COMPUTE | C31: RN-SIDE24-POINT-LAW-20260920-v1 | D31: READY | E31: Review normalized periodized kernel and complete order0..4 image tails; derivative signs, nine-pin affine law, interval LDL/Schur inclusion and PSD premise; replay M4/S4/y2 witnesses and Holder bound at y=(1,1). Verify all source and scope boundaries. | F31: https://drive.google.com/file/d/1nzc7GJeAR06L03c6y8Kf958VHU4n-mJ_/view | G31: 503 source-exposed nonauthor code checks; 342 Decimal diagnostics; preimplementation source suggestions disclosed. Code-check PASS only, organizational independence0. | H31: SCIENTIFIC REVIEW OPEN / 0 INDEPENDENCE CREDIT | I31: 2026-09-20T04:29:09.031711+00:00 | J31: New exact point-law candidate; earlier RN routes unchanged. | L31: =IF(I31="","",MAX(0,TODAY()-DATE(VALUE(LEFT(I31,4)),VALUE(MID(I31,6,2)),VALUE(MID(I31,9,2))))) -> 3 | M31: =IF(L31="","UNKNOWN",IF(D31="PASS_TECHNICAL","EXTERNAL ONLY",IF(L31>=30,"ESCALATE",IF(L31>=14,"DECOMPOSE",IF(L31>=7,"PRIORITIZE","NEW"))))) -> NEW | N31: OpenAI / Codex / task 01a0bbb5-2fcb-77f0-b78b-4d220ddd7ab2 | O31: d953aa0ee6aa08ee178ad21a4c01caeb307ede5d97b14b3b1b282e4d214f5753 | P31: 20773 | Q31: UNASSIGNED | S31: No density/window factor, H3 normalizer, spatial cover, remote budget, all-small-r theorem or canonical promotion. Private GitHub publication; scientific review remains open.
A32: RV-RN-SIDE24-DENSITY-WINDOW-20260920-v1 | B32: MATH / COMPUTE | C32: RN-SIDE24-DENSITY-WINDOW-20260920-v1 | D32: READY | E32: Review six-pin conditional jet, gradient LDL density, gradient-zero height mean/variance and full-window nearest-distance cap; compose whole-mark M4/S4/y2 bound with imported H3 floor in original Hessian units. Verify source basis, exact scope and numerical negative controls. | F32: https://drive.google.com/file/d/1BP6EjmOeezUlH3aLID4N2Qc-wun5RR8C/view | G32: 37 source-exposed nonauthor audit checks; 7 report mutations rejected; 17 Decimal quantities and five joint-density comparisons. Prior suggestions disclosed; zero organizational independence. | H32: SCIENTIFIC REVIEW OPEN / 0 INDEPENDENCE CREDIT | I32: 2026-09-20T05:00:48.931972+00:00 | J32: New exact density/window candidate; earlier RN routes unchanged. | L32: =IF(I32="","",MAX(0,TODAY()-DATE(VALUE(LEFT(I32,4)),VALUE(MID(I32,6,2)),VALUE(MID(I32,9,2))))) -> 3 | M32: =IF(L32="","UNKNOWN",IF(D32="PASS_TECHNICAL","EXTERNAL ONLY",IF(L32>=30,"ESCALATE",IF(L32>=14,"DECOMPOSE",IF(L32>=7,"PRIORITIZE","NEW"))))) -> NEW | N32: OpenAI / Codex / task 01a0bbb5-2fcb-77f0-b78b-4d220ddd7ab2 | O32: c53bf5989aceb258f28aeabb4ff8f4359a968094916929e06552185be2146310 | P32: 15286 | Q32: UNASSIGNED | S32: H3 imported hypothesis not reproved; no spatial integral/cover, remote-budget closure, all-small-r theorem or canonical promotion. Private draft publication; recurring hourly execution does not alter scientific gates.
A33: RV-RN-SPATIAL-PARALLEL-MATH-20260920-v1 | B33: MATH / COMPUTE | C33: RN-SPATIAL-PARALLEL-MATH-20260920-v1 | D33: READY | E33: Review Gaussian L2 mean/covariance spatial transport, six-pin then gradient/mark conditioning, 4/4/2 witnesses, complete four-cell area sum; fixed-r H3 safe-box quartic and r² scale; LPW full spectral tails/quadratic profiles; c2 cancellation-preserving band. Check scope separation and strict typed candidate replay. | F33: https://drive.google.com/file/d/13a9tebHQ7URIEE9qtAO499Ju6oLznuyG/view | G33: 33 checks, 2406 tests passed, 1 existing skip. Cell review91 tests,6375 Decimal diagnostic inclusions; same-provider, independence0. Parent cross-target H3 review reconstructs saved-law quartic; original artifacts preserved. | H33: SCIENTIFIC REVIEW OPEN / 0 INDEPENDENCE CREDIT | I33: 2026-09-20T06:01:06.985303+00:00 | J33: Four scoped candidates; full near annulus and wider claims unchanged. | L33: =IF(I33="","",MAX(0,TODAY()-DATE(VALUE(LEFT(I33,4)),VALUE(MID(I33,6,2)),VALUE(MID(I33,9,2))))) -> 3 | M33: =IF(L33="","UNKNOWN",IF(D33="PASS_TECHNICAL","EXTERNAL ONLY",IF(L33>=30,"ESCALATE",IF(L33>=14,"DECOMPOSE",IF(L33>=7,"PRIORITIZE","NEW"))))) -> NEW | N33: OpenAI / Codex / task 01a0bbb5-2fcb-77f0-b78b-4d220ddd7ab2 | O33: 4bd14f065f98afca128c50e7ab83d267f146ca771313a489fe9196f06ed8de33 | P33: 21408 | Q33: UNASSIGNED | S33: RN full annulus/remote budget/all-r open. H3 original lower floor re-proved only at fixedr; original upper interval not replayed. LPW endpoint/model premises retained. H5 onejet/candidateband only; zero status promotions. Private proof/bundle.
A34: RV-Q0-TWELVE-MATH-20260920-v1 | B34: MATH / COMPUTE | C34: Q0-TWELVE-MATH-20260920-v1 | D34: READY | E34: Review H3 covariance/typed limit and fixed-r ceiling; LPW conditional regression and elder-pairing scope; unconditional two-jet bands; persistence event interface, contact Jacobians, full-mark tail hypotheses, WP conditioning-first loss, Lambda replacements, Gaussian tube success ball, optimized integer-count and eta identities | F34: https://drive.google.com/file/d/11mOqEy1T7YGgEbW35EhOs5So68I-ZaBR/view | G34: 34 checks, 2460 tests passed, 1 existing skip; twelve exact original-report replays. Same-provider technical review; independence0. Original proofs and source archive are immutable; exact portable replay and corrupt-input controls recorded. | H34: SCIENTIFIC REVIEW OPEN / 0 INDEPENDENCE CREDIT | I34: 2026-09-20T06:49:53.343184+00:00 | J34: Twelve scoped candidates; actual all-angle/weighted-field/continuum interfaces remain open. | L34: =IF(I34="","",MAX(0,TODAY()-DATE(VALUE(LEFT(I34,4)),VALUE(MID(I34,6,2)),VALUE(MID(I34,9,2))))) -> 3 | M34: =IF(L34="","UNKNOWN",IF(D34="PASS_TECHNICAL","EXTERNAL ONLY",IF(L34>=30,"ESCALATE",IF(L34>=14,"DECOMPOSE",IF(L34>=7,"PRIORITIZE","NEW"))))) -> NEW | N34: OpenAI / Codex / task 01a0bbb5-2fcb-77f0-b78b-4d220ddd7ab2 | O34: 3cdb13fa4b8f6502b5e97b8f4cac5c212bb259a11b4bf2d4896f0db8b42a4436 | P34: 17480 | Q34: UNASSIGNED | S34: No canonical promotion. LPW event firewall preserved; H3 lower radius existential, ceiling fixed-r. Synthetic tail/WP/Lambda/tube constants not actual field certificates. Private proof/bundle.
